Workbook

Sheet 통합
A1: 2026년 금융·보증 통합 사업계획
A2: 단위: 원 ｜ 역년(CY)2026 1~12월 ｜ 금융·보증 탭 셀 직접 참조 → 실적 입력 시 전부 자동 갱신
A3: 구분 | B3: 1월 | C3: 2월 | D3: 3월 | E3: 4월 | F3: 5월 | G3: 6월 | H3: 7월 | I3: 8월 | J3: 9월 | K3: 10월 | L3: 11월 | M3: 12월 | N3: 연간 합계
A4: Ⅰ. 거래 / 실행 규모 (금융=여신액 ｜ 보증=결제액)
A5: 금융 여신액 (계획) | B5: ='금융'!B7 | C5: ='금융'!C7 | D5: ='금융'!D7 | E5: ='금융'!E7 | F5: ='금융'!F7 | G5: ='금융'!G7 | H5: ='금융'!H7 | I5: ='금융'!I7 | ... N5: ='금융'!N7
A6: 금융 여신액 (실적) | B6: ='금융'!B17 | C6: ='금융'!C17 | D6: ='금융'!D17 | E6: ='금융'!E17 | F6: ='금융'!F17 | G6: ='금융'!G17 | H6: ='금융'!H17 | I6: ='금융'!I17 | ... N6: ='금융'!N17
A7: 금융 여신액 달성률 | B7: =IF(B6=0,"",IFERROR(B6/B5,"")) | C7: =IF(C6=0,"",IFERROR(C6/C5,"")) | D7: =IF(D6=0,"",IFERROR(D6/D5,"")) | E7: =IF(E6=0,"",IFERROR(E6/E5,"")) | F7: =IF(F6=0,"",IFERROR(F6/F5,"")) | G7: =IF(G6=0,"",IFERROR(G6/G5,"")) | H7: =IF(H6=0,"",IFERROR(H6/H5,"")) | I7: =IF(I6=0,"",IFERROR(I6/I5,"")) | ... N7: =IF(N6=0,"",IFERROR(N6/N5,""))
A8: 보증 결제액 (계획) | B8: ='보증'!B7 | C8: ='보증'!C7 | D8: ='보증'!D7 | E8: ='보증'!E7 | F8: ='보증'!F7 | G8: ='보증'!G7 | H8: ='보증'!H7 | I8: ='보증'!I7 | ... N8: ='보증'!N7
A9: 보증 결제액 (실적) | B9: ='보증'!B18 | C9: ='보증'!C18 | D9: ='보증'!D18 | E9: ='보증'!E18 | F9: ='보증'!F18 | G9: ='보증'!G18 | H9: ='보증'!H18 | I9: ='보증'!I18 | ... N9: ='보증'!N18
A10: 보증 결제액 달성률 | B10: =IF(B9=0,"",IFERROR(B9/B8,"")) | C10: =IF(C9=0,"",IFERROR(C9/C8,"")) | D10: =IF(D9=0,"",IFERROR(D9/D8,"")) | E10: =IF(E9=0,"",IFERROR(E9/E8,"")) | F10: =IF(F9=0,"",IFERROR(F9/F8,"")) | G10: =IF(G9=0,"",IFERROR(G9/G8,"")) | H10: =IF(H9=0,"",IFERROR(H9/H8,"")) | I10: =IF(I9=0,"",IFERROR(I9/I8,"")) | ... N10: =IF(N9=0,"",IFERROR(N9/N8,""))
A12: Ⅱ. 매출 (금융=본업+광고 ｜ 보증=가입+광고)
A13: 금융 매출 (계획) | B13: ='금융'!B32 | C13: ='금융'!C32 | D13: ='금융'!D32 | E13: ='금융'!E32 | F13: ='금융'!F32 | G13: ='금융'!G32 | H13: ='금융'!H32 | I13: ='금융'!I32 | ... N13: ='금융'!N32
A14: 금융 매출 (실적) | B14: ='금융'!B46 | C14: ='금융'!C46 | D14: ='금융'!D46 | E14: ='금융'!E46 | F14: ='금융'!F46 | G14: ='금융'!G46 | H14: ='금융'!H46 | I14: ='금융'!I46 | ... N14: ='금융'!N46
A15: 금융 매출 달성률 | B15: =IF(B14=0,"",IFERROR(B14/B13,"")) | C15: =IF(C14=0,"",IFERROR(C14/C13,"")) | D15: =IF(D14=0,"",IFERROR(D14/D13,"")) | E15: =IF(E14=0,"",IFERROR(E14/E13,"")) | F15: =IF(F14=0,"",IFERROR(F14/F13,"")) | G15: =IF(G14=0,"",IFERROR(G14/G13,"")) | H15: =IF(H14=0,"",IFERROR(H14/H13,"")) | I15: =IF(I14=0,"",IFERROR(I14/I13,"")) | ... N15: =IF(N14=0,"",IFERROR(N14/N13,""))
A16: 보증 매출 (계획) | B16: ='보증'!B7 | C16: ='보증'!C7 | D16: ='보증'!D7 | E16: ='보증'!E7 | F16: ='보증'!F7 | G16: ='보증'!G7 | H16: ='보증'!H7 | I16: ='보증'!I7 | ... N16: ='보증'!N7
A17: 보증 매출 (실적) | B17: ='보증'!B18 | C17: ='보증'!C18 | D17: ='보증'!D18 | E17: ='보증'!E18 | F17: ='보증'!F18 | G17: ='보증'!G18 | H17: ='보증'!H18 | I17: ='보증'!I18 | ... N17: ='보증'!N18
A18: 보증 매출 달성률 | B18: =IF(B17=0,"",IFERROR(B17/B16,"")) | C18: =IF(C17=0,"",IFERROR(C17/C16,"")) | D18: =IF(D17=0,"",IFERROR(D17/D16,"")) | E18: =IF(E17=0,"",IFERROR(E17/E16,"")) | F18: =IF(F17=0,"",IFERROR(F17/F16,"")) | G18: =IF(G17=0,"",IFERROR(G17/G16,"")) | H18: =IF(H17=0,"",IFERROR(H17/H16,"")) | I18: =IF(I17=0,"",IFERROR(I17/I16,"")) | ... N18: =IF(N17=0,"",IFERROR(N17/N16,""))
A20: Ⅲ. 통합 매출 합계 (금융 + 보증)
A21: 통합 매출 (계획) | B21: =B13+B16 | C21: =C13+C16 | D21: =D13+D16 | E21: =E13+E16 | F21: =F13+F16 | G21: =G13+G16 | H21: =H13+H16 | I21: =I13+I16 | ... N21: =N13+N16
A22: 통합 매출 (실적) | B22: =B14+B17 | C22: =C14+C17 | D22: =D14+D17 | E22: =E14+E17 | F22: =F14+F17 | G22: =G14+G17 | H22: =H14+H17 | I22: =I14+I17 | ... N22: =N14+N17
A23: 통합 매출 달성률 | B23: =IF(B22=0,"",IFERROR(B22/B21,"")) | C23: =IF(C22=0,"",IFERROR(C22/C21,"")) | D23: =IF(D22=0,"",IFERROR(D22/D21,"")) | E23: =IF(E22=0,"",IFERROR(E22/E21,"")) | F23: =IF(F22=0,"",IFERROR(F22/F21,"")) | G23: =IF(G22=0,"",IFERROR(G22/G21,"")) | H23: =IF(H22=0,"",IFERROR(H22/H21,"")) | I23: =IF(I22=0,"",IFERROR(I22/I21,"")) | ... N23: =IF(N22=0,"",IFERROR(N22/N21,""))

Sheet 금융
A1: 2026년 금융 사업계획 (CY26)
A2: 단위: 원 ｜ 메인지표=여신액 ｜ H/S금융=선불(일반금융)+후불(EP금융), 신규=금융플러스+엔카페이2.0 ｜ 노란칸=실적 입력 ｜ 회색=자동합계 수식
A3: 구분 | B3: 1월 | C3: 2월 | D3: 3월 | E3: 4월 | F3: 5월 | G3: 6월 | H3: 7월 | I3: 8월 | J3: 9월 | K3: 10월 | L3: 11월 | M3: 12월 | N3: 연간 합계
A4: OKR ▷ Objective: 월 평균 여신액 증가분 (KR1 기존 소매금융 / KR2 신규 소매금융)
A5: Ⅰ. 여신액 (메인)
A6: [계획]
A7: 총 여신액 | B7: =B8+B13 | C7: =C8+C13 | D7: =D8+D13 | E7: =E8+E13 | F7: =F8+F13 | G7: =G8+G13 | H7: =H8+H13 | I7: =I8+I13 | ... M7: =M8+M13 | N7: =SUM(B7:M7)
A8: 1. 기존 소매금융 | B8: =B9+B12 | C8: =C9+C12 | D8: =D9+D12 | E8: =E9+E12 | F8: =F9+F12 | G8: =G9+G12 | H8: =H9+H12 | I8: =I9+I12 | ... M8: =M9+M12 | N8: =SUM(B8:M8)
A9: (1) H/S 금융 | B9: =B10+B11 | C9: =C10+C11 | D9: =D10+D11 | E9: =E10+E11 | F9: =F10+F11 | G9: =G10+G11 | H9: =H10+H11 | I9: =I10+I11 | ... M9: =M10+M11 | N9: =SUM(B9:M9)
A10: 선불 · 일반금융 여신액 | B10: 7700000000 | C10: 7500000000 | D10: 7600000000 | E10: 7600000000 | F10: 6750000000 | G10: 7100000000 | H10: 10950000000 | I10: 9500000000 | J10: 9200000000 | K10: 8950000000 | L10: 7650000000 | M10: 8500000000 | N10: =SUM(B10:M10)
A11: 후불 · EP 금융 여신액 | B11: 3080000000 | C11: 3000000000 | D11: 3040000000 | E11: 3040000000 | F11: 2700000000 | G11: 2840000000 | H11: 4380000000 | I11: 3800000000 | J11: 3680000000 | K11: 3580000000 | L11: 3060000000 | M11: 3400000000 | N11: =SUM(B11:M11)
A12: (2) 일반 금융 | B12: 4620000000 | C12: 4500000000 | D12: 4560000000 | E12: 4560000000 | F12: 4050000000 | G12: 4260000000 | H12: 6570000000 | I12: 5700000000 | J12: 5520000000 | K12: 5370000000 | L12: 4590000000 | M12: 5100000000 | N12: =SUM(B12:M12)
A13: 2. 신규 소매금융 | B13: =B14+B15 | C13: =C14+C15 | D13: =D14+D15 | E13: =E14+E15 | F13: =F14+F15 | G13: =G14+G15 | H13: =H14+H15 | I13: =I14+I15 | ... M13: =M14+M15 | N13: =SUM(B13:M13)
A14: (1) 금융 플러스 | B14: 0 | C14: 100000000 | D14: 300000000 | E14: 600000000 | F14: 1000000000 | G14: 2000000000 | H14: 4100000000 | I14: 3600000000 | J14: 3300000000 | K14: 3100000000 | L14: 2600000000 | M14: 3300000000 | N14: =SUM(B14:M14)
A15: (2) 엔카페이 2.0 (EP 2.0) | B15: 0 | C15: 0 | D15: 0 | E15: 800000000 | F15: 1100000000 | G15: 2000000000 | H15: 4000000000 | I15: 3800000000 | J15: 3400000000 | K15: 3300000000 | L15: 2300000000 | M15: 3300000000 | N15: =SUM(B15:M15)
A16: [실적]
A17: 총 여신액 | B17: =B18+B23 | C17: =C18+C23 | D17: =D18+D23 | E17: =E18+E23 | F17: =F18+F23 | G17: =G18+G23 | H17: =H18+H23 | I17: =I18+I23 | ... M17: =M18+M23 | N17: =SUM(B17:M17)
A18: 1. 기존 소매금융 | B18: =B19+B22 | C18: =C19+C22 | D18: =D19+D22 | E18: =E19+E22 | F18: =F19+F22 | G18: =G19+G22 | H18: =H19+H22 | I18: =I19+I22 | ... M18: =M19+M22 | N18: =SUM(B18:M18)
A19: (1) H/S 금융 | B19: =B20+B21 | C19: =C20+C21 | D19: =D20+D21 | E19: =E20+E21 | F19: =F20+F21 | G19: =G20+G21 | H19: =H20+H21 | I19: =I20+I21 | ... M19: =M20+M21 | N19: =SUM(B19:M19)
A20: 선불 · 일반금융 여신액 | B20: =SUMIFS(Raw_금융!I:I, Raw_금융!A:A, "1월", Raw_금융!AB:AB, "홈서비스", Raw_금융!E:E, "<>현대EP")+SUMIFS(Raw_금융!I:I, Raw_금융!A:A, "1월", Raw_금융!AB:AB, "믿고", Raw_금융!E:E, "<>현대EP") | C20: =SUMIFS(Raw_금융!I:I, Raw_금융!A:A, "2월", Raw_금융!AB:AB, "홈서비스", Raw_금융!E:E, "<>현대EP")+SUMIFS(Raw_금융!I:I, Raw_금융!A:A, "2월", Raw_금융!AB:AB, "믿고", Raw_금융!E:E, "<>현대EP") | D20: =SUMIFS(Raw_금융!I:I, Raw_금융!A:A, "3월", Raw_금융!AB:AB, "홈서비스", Raw_금융!E:E, "<>현대EP")+SUMIFS(Raw_금융!I:I, Raw_금융!A:A, "3월", Raw_금융!AB:AB, "믿고", Raw_금융!E:E, "<>현대EP") | E20: =SUMIFS(Raw_금융!I:I, Raw_금융!A:A, "4월", Raw_금융!AB:AB, "홈서비스", Raw_금융!E:E, "<>현대EP")+SUMIFS(Raw_금융!I:I, Raw_금융!A:A, "4월", Raw_금융!AB:AB, "믿고", Raw_금융!E:E, "<>현대EP") | F20: =SUMIFS(Raw_금융!I:I, Raw_금융!A:A, "5월", Raw_금융!AB:AB, "홈서비스", Raw_금융!E:E, "<>현대EP")+SUMIFS(Raw_금융!I:I, Raw_금융!A:A, "5월", Raw_금융!AB:AB, "믿고", Raw_금융!E:E, "<>현대EP") | G20: =SUMIFS(Raw_금융!I:I, Raw_금융!A:A, "6월", Raw_금융!AB:AB, "홈서비스", Raw_금융!E:E, "<>현대EP")+SUMIFS(Raw_금융!I:I, Raw_금융!A:A, "6월", Raw_금융!AB:AB, "믿고", Raw_금융!E:E, "<>현대EP") | H20: =SUMIFS(Raw_금융!I:I, Raw_금융!A:A, "7월", Raw_금융!AB:AB, "홈서비스", Raw_금융!E:E, "<>현대EP")+SUMIFS(Raw_금융!I:I, Raw_금융!A:A, "7월", Raw_금융!AB:AB, "믿고", Raw_금융!E:E, "<>현대EP") | I20: =SUMIFS(Raw_금융!I:I, Raw_금융!A:A, "8월", Raw_금융!AB:AB, "홈서비스", Raw_금융!E:E, "<>현대EP")+SUMIFS(Raw_금융!I:I, Raw_금융!A:A, "8월", Raw_금융!AB:AB, "믿고", Raw_금융!E:E, "<>현대EP") | J20: =SUMIFS(Raw_금융!I:I, Raw_금융!A:A, "9월", Raw_금융!AB:AB, "홈서비스", Raw_금융!E:E, "<>현대EP")+SUMIFS(Raw_금융!I:I, Raw_금융!A:A, "9월", Raw_금융!AB:AB, "믿고", Raw_금융!E:E, "<>현대EP") | K20: =SUMIFS(Raw_금융!I:I, Raw_금융!A:A, "10월", Raw_금융!AB:AB, "홈서비스", Raw_금융!E:E, "<>현대EP")+SUMIFS(Raw_금융!I:I, Raw_금융!A:A, "10월", Raw_금융!AB:AB, "믿고", Raw_금융!E:E, "<>현대EP") | L20: =SUMIFS(Raw_금융!I:I, Raw_금융!A:A, "11월", Raw_금융!AB:AB, "홈서비스", Raw_금융!E:E, "<>현대EP")+SUMIFS(Raw_금융!I:I, Raw_금융!A:A, "11월", Raw_금융!AB:AB, "믿고", Raw_금융!E:E, "<>현대EP") | M20: =SUMIFS(Raw_금융!I:I, Raw_금융!A:A, "12월", Raw_금융!AB:AB, "홈서비스", Raw_금융!E:E, "<>현대EP")+SUMIFS(Raw_금융!I:I, Raw_금융!A:A, "12월", Raw_금융!AB:AB, "믿고", Raw_금융!E:E, "<>현대EP") | N20: =SUM(B20:M20)
A21: 후불 · EP 금융 여신액 | B21: =SUMIFS(Raw_금융!I:I, Raw_금융!A:A, "1월", Raw_금융!AB:AB, "홈서비스", Raw_금융!E:E, "현대EP")+SUMIFS(Raw_금융!I:I, Raw_금융!A:A, "1월", Raw_금융!AB:AB, "믿고", Raw_금융!E:E, "현대EP") | C21: =SUMIFS(Raw_금융!I:I, Raw_금융!A:A, "2월", Raw_금융!AB:AB, "홈서비스", Raw_금융!E:E, "현대EP")+SUMIFS(Raw_금융!I:I, Raw_금융!A:A, "2월", Raw_금융!AB:AB, "믿고", Raw_금융!E:E, "현대EP") | D21: =SUMIFS(Raw_금융!I:I, Raw_금융!A:A, "3월", Raw_금융!AB:AB, "홈서비스", Raw_금융!E:E, "현대EP")+SUMIFS(Raw_금융!I:I, Raw_금융!A:A, "3월", Raw_금융!AB:AB, "믿고", Raw_금융!E:E, "현대EP") | E21: =SUMIFS(Raw_금융!I:I, Raw_금융!A:A, "4월", Raw_금융!AB:AB, "홈서비스", Raw_금융!E:E, "현대EP")+SUMIFS(Raw_금융!I:I, Raw_금융!A:A, "4월", Raw_금융!AB:AB, "믿고", Raw_금융!E:E, "현대EP") | F21: =SUMIFS(Raw_금융!I:I, Raw_금융!A:A, "5월", Raw_금융!AB:AB, "홈서비스", Raw_금융!E:E, "현대EP")+SUMIFS(Raw_금융!I:I, Raw_금융!A:A, "5월", Raw_금융!AB:AB, "믿고", Raw_금융!E:E, "현대EP") | G21: =SUMIFS(Raw_금융!I:I, Raw_금융!A:A, "6월", Raw_금융!AB:AB, "홈서비스", Raw_금융!E:E, "현대EP")+SUMIFS(Raw_금융!I:I, Raw_금융!A:A, "6월", Raw_금융!AB:AB, "믿고", Raw_금융!E:E, "현대EP") | H21: =SUMIFS(Raw_금융!I:I, Raw_금융!A:A, "7월", Raw_금융!AB:AB, "홈서비스", Raw_금융!E:E, "현대EP")+SUMIFS(Raw_금융!I:I, Raw_금융!A:A, "7월", Raw_금융!AB:AB, "믿고", Raw_금융!E:E, "현대EP") | I21: =SUMIFS(Raw_금융!I:I, Raw_금융!A:A, "8월", Raw_금융!AB:AB, "홈서비스", Raw_금융!E:E, "현대EP")+SUMIFS(Raw_금융!I:I, Raw_금융!A:A, "8월", Raw_금융!AB:AB, "믿고", Raw_금융!E:E, "현대EP") | J21: =SUMIFS(Raw_금융!I:I, Raw_금융!A:A, "9월", Raw_금융!AB:AB, "홈서비스", Raw_금융!E:E, "현대EP")+SUMIFS(Raw_금융!I:I, Raw_금융!A:A, "9월", Raw_금융!AB:AB, "믿고", Raw_금융!E:E, "현대EP") | K21: =SUMIFS(Raw_금융!I:I, Raw_금융!A:A, "10월", Raw_금융!AB:AB, "홈서비스", Raw_금융!E:E, "현대EP")+SUMIFS(Raw_금융!I:I, Raw_금융!A:A, "10월", Raw_금융!AB:AB, "믿고", Raw_금융!E:E, "현대EP") | L21: =SUMIFS(Raw_금융!I:I, Raw_금융!A:A, "11월", Raw_금융!AB:AB, "홈서비스", Raw_금융!E:E, "현대EP")+SUMIFS(Raw_금융!I:I, Raw_금융!A:A, "11월", Raw_금융!AB:AB, "믿고", Raw_금융!E:E, "현대EP") | M21: =SUMIFS(Raw_금융!I:I, Raw_금융!A:A, "12월", Raw_금융!AB:AB, "홈서비스", Raw_금융!E:E, "현대EP")+SUMIFS(Raw_금융!I:I, Raw_금융!A:A, "12월", Raw_금융!AB:AB, "믿고", Raw_금융!E:E, "현대EP") | N21: =SUM(B21:M21)
A22: (2) 일반 금융 | B22: =SUMIFS(Raw_금융!I:I, Raw_금융!A:A, "1월", Raw_금융!AB:AB, "엔카") | C22: =SUMIFS(Raw_금융!I:I, Raw_금융!A:A, "2월", Raw_금융!AB:AB, "엔카") | D22: =SUMIFS(Raw_금융!I:I, Raw_금융!A:A, "3월", Raw_금융!AB:AB, "엔카") | E22: =SUMIFS(Raw_금융!I:I, Raw_금융!A:A, "4월", Raw_금융!AB:AB, "엔카") | F22: =SUMIFS(Raw_금융!I:I, Raw_금융!A:A, "5월", Raw_금융!AB:AB, "엔카") | G22: =SUMIFS(Raw_금융!I:I, Raw_금융!A:A, "6월", Raw_금융!AB:AB, "엔카") | H22: =SUMIFS(Raw_금융!I:I, Raw_금융!A:A, "7월", Raw_금융!AB:AB, "엔카") | I22: =SUMIFS(Raw_금융!I:I, Raw_금융!A:A, "8월", Raw_금융!AB:AB, "엔카") | J22: =SUMIFS(Raw_금융!I:I, Raw_금융!A:A, "9월", Raw_금융!AB:AB, "엔카") | K22: =SUMIFS(Raw_금융!I:I, Raw_금융!A:A, "10월", Raw_금융!AB:AB, "엔카") | L22: =SUMIFS(Raw_금융!I:I, Raw_금융!A:A, "11월", Raw_금융!AB:AB, "엔카") | M22: =SUMIFS(Raw_금융!I:I, Raw_금융!A:A, "12월", Raw_금융!AB:AB, "엔카") | N22: =SUM(B22:M22)
A23: 2. 신규 소매금융 | B23: =B24+B25 | C23: =C24+C25 | D23: =D24+D25 | E23: =E24+E25 | F23: =F24+F25 | G23: =G24+G25 | H23: =H24+H25 | I23: =I24+I25 | ... M23: =M24+M25 | N23: =SUM(B23:M23)
A24: (1) 금융 플러스 | B24: =SUMIFS(Raw_금융!I:I, Raw_금융!A:A, "1월", Raw_금융!AB:AB, "딜러유입") | C24: =SUMIFS(Raw_금융!I:I, Raw_금융!A:A, "2월", Raw_금융!AB:AB, "딜러유입") | D24: =SUMIFS(Raw_금융!I:I, Raw_금융!A:A, "3월", Raw_금융!AB:AB, "딜러유입") | E24: =SUMIFS(Raw_금융!I:I, Raw_금융!A:A, "4월", Raw_금융!AB:AB, "딜러유입") | F24: =SUMIFS(Raw_금융!I:I, Raw_금융!A:A, "5월", Raw_금융!AB:AB, "딜러유입") | G24: =SUMIFS(Raw_금융!I:I, Raw_금융!A:A, "6월", Raw_금융!AB:AB, "딜러유입") | H24: =SUMIFS(Raw_금융!I:I, Raw_금융!A:A, "7월", Raw_금융!AB:AB, "딜러유입") | I24: =SUMIFS(Raw_금융!I:I, Raw_금융!A:A, "8월", Raw_금융!AB:AB, "딜러유입") | J24: =SUMIFS(Raw_금융!I:I, Raw_금융!A:A, "9월", Raw_금융!AB:AB, "딜러유입") | K24: =SUMIFS(Raw_금융!I:I, Raw_금융!A:A, "10월", Raw_금융!AB:AB, "딜러유입") | L24: =SUMIFS(Raw_금융!I:I, Raw_금융!A:A, "11월", Raw_금융!AB:AB, "딜러유입") | M24: =SUMIFS(Raw_금융!I:I, Raw_금융!A:A, "12월", Raw_금융!AB:AB, "딜러유입") | N24: =SUM(B24:M24)
A25: (2) 엔카페이 2.0 (EP 2.0) | N25: =SUM(B25:M25)
A26: 여신액 달성률 (총) | B26: =IF(B17=0,"",IFERROR(B17/B7,"")) | C26: =IF(C17=0,"",IFERROR(C17/C7,"")) | D26: =IF(D17=0,"",IFERROR(D17/D7,"")) | E26: =IF(E17=0,"",IFERROR(E17/E7,"")) | F26: =IF(F17=0,"",IFERROR(F17/F7,"")) | G26: =IF(G17=0,"",IFERROR(G17/G7,"")) | H26: =IF(H17=0,"",IFERROR(H17/H7,"")) | I26: =IF(I17=0,"",IFERROR(I17/I7,"")) | ... N26: =IF(N17=0,"",IFERROR(N17/N7,""))
A27: └ 기존 소매금융 | B27: =IF(B18=0,"",IFERROR(B18/B8,"")) | C27: =IF(C18=0,"",IFERROR(C18/C8,"")) | D27: =IF(D18=0,"",IFERROR(D18/D8,"")) | E27: =IF(E18=0,"",IFERROR(E18/E8,"")) | F27: =IF(F18=0,"",IFERROR(F18/F8,"")) | G27: =IF(G18=0,"",IFERROR(G18/G8,"")) | H27: =IF(H18=0,"",IFERROR(H18/H8,"")) | I27: =IF(I18=0,"",IFERROR(I18/I8,"")) | ... N27: =IF(N18=0,"",IFERROR(N18/N8,""))
A28: └ 신규 소매금융 | B28: =IF(B23=0,"",IFERROR(B23/B13,"")) | C28: =IF(C23=0,"",IFERROR(C23/C13,"")) | D28: =IF(D23=0,"",IFERROR(D23/D13,"")) | E28: =IF(E23=0,"",IFERROR(E23/E13,"")) | F28: =IF(F23=0,"",IFERROR(F23/F13,"")) | G28: =IF(G23=0,"",IFERROR(G23/G13,"")) | H28: =IF(H23=0,"",IFERROR(H23/H13,"")) | I28: =IF(I23=0,"",IFERROR(I23/I13,"")) | ... N28: =IF(N23=0,"",IFERROR(N23/N13,""))
A30: Ⅱ. 매출 (본업 + 연계 광고)
A31: [계획]
A32: 총 매출액 | B32: =B33+B42 | C32: =C33+C42 | D32: =D33+D42 | E32: =E33+E42 | F32: =F33+F42 | G32: =G33+G42 | H32: =H33+H42 | I32: =I33+I42 | ... M32: =M33+M42 | N32: =SUM(B32:M32)
A33: Ⅰ. 금융 매출 | B33: =B34+B39 | C33: =C34+C39 | D33: =D34+D39 | E33: =E34+E39 | F33: =F34+F39 | G33: =G34+G39 | H33: =H34+H39 | I33: =I34+I39 | ... M33: =M34+M39 | N33: =SUM(B33:M33)
A34: 1. 기존 소매금융 | B34: =B35+B38 | C34: =C35+C38 | D34: =D35+D38 | E34: =E35+E38 | F34: =F35+F38 | G34: =G35+G38 | H34: =H35+H38 | I34: =I35+I38 | ... M34: =M35+M38 | N34: =SUM(B34:M34)
A35: (1) H/S 금융 | B35: =B36+B37 | C35: =C36+C37 | D35: =D36+D37 | E35: =E36+E37 | F35: =F36+F37 | G35: =G36+G37 | H35: =H36+H37 | I35: =I36+I37 | ... M35: =M36+M37 | N35: =SUM(B35:M35)
A36: 선불 · 일반금융 매출 | B36: 88994410 | C36: 97932867 | D36: 99238639 | E36: 99238639 | F36: 88139580 | G36: 92709781 | H36: 142981986 | I36: 1.240483e+08 | J36: 1.2013098e+08 | K36: 1.1686655e+08 | L36: 99891524 | M36: 1.1099058e+08 | N36: =SUM(B36:M36)
A37: 후불 · EP 금융 매출 | B37: 46171014 | C37: 44971767 | D37: 45571390 | E37: 45571390 | F37: 40474590 | G37: 42573272 | H37: 65658779 | I37: 56964238 | J37: 55165367 | K37: 53666308 | L37: 45871202 | M37: 50968002 | N37: =SUM(B37:M37)
A38: (2) 일반 금융 | B38: 53441641 | C38: 58803546 | D38: 59587593 | E38: 59587593 | F38: 52923191 | G38: 55667357 | H38: 85853177 | I38: 74484492 | J38: 72132350 | K38: 70172232 | L38: 59979617 | M38: 66644019 | N38: =SUM(B38:M38)
A39: 2. 신규 소매금융 | B39: =B40+B41 | C39: =C40+C41 | D39: =D40+D41 | E39: =E40+E41 | F39: =F40+F41 | G39: =G40+G41 | H39: =H40+H41 | I39: =I40+I41 | ... M39: =M40+M41 | N39: =SUM(B39:M39)
A40: (1) 금융 플러스 | B40: 0 | C40: 1000000 | D40: 3000000 | E40: 6000000 | F40: 10000000 | G40: 20000000 | H40: 41000000 | I40: 36000000 | J40: 33000000 | K40: 31000000 | L40: 26000000 | M40: 33000000 | N40: =SUM(B40:M40)
A41: (2) 엔카페이 2.0 | B41: 0 | C41: 0 | D41: 0 | E41: 4800000 | F41: 6600000 | G41: 12000000 | H41: 24000000 | I41: 22800000 | J41: 20400000 | K41: 19800000 | L41: 13800000 | M41: 19800000 | N41: =SUM(B41:M41)
...

Sheet 보증
A1: 2026년 보증 사업계획 (역년 환산)
A2: 단위: 원 ｜ 메인지표=매출(결제액 기준) ｜ 보증 회계연도(FY)→역년2026 환산 ｜ 매출=가입+광고+정비 ｜ 노란칸=실적 입력
A3: 구분 | B3: 1월 | C3: 2월 | D3: 3월 | E3: 4월 | F3: 5월 | G3: 6월 | H3: 7월 | I3: 8월 | J3: 9월 | K3: 10월 | L3: 11월 | M3: 12월 | N3: 연간 합계
A4: OKR ▷ KR1 EW 커버리지확장 월평균매출 4.5억 / KR2 정비 월평균매출 0.5억 / KR3 스케일업 기반
A5: Ⅰ. 사업 매출 (메인, 결제액 기준 = 가입+광고+정비)
A6: [계획]
A7: 사업 매출 (거래액 총계) | B7: =B8+B13+B14+B15+B16 | C7: =C8+C13+C14+C15+C16 | D7: =D8+D13+D14+D15+D16 | E7: =E8+E13+E14+E15+E16 | F7: =F8+F13+F14+F15+F16 | G7: =G8+G13+G14+G15+G16 | H7: =H8+H13+H14+H15+H16 | I7: =I8+I13+I14+I15+I16 | ... M7: =M8+M13+M14+M15+M16 | N7: =SUM(B7:M7)
A8: 총 가입 거래액 | B8: =B9+B10+B11+B12 | C8: =C9+C10+C11+C12 | D8: =D9+D10+D11+D12 | E8: =E9+E10+E11+E12 | F8: =F9+F10+F11+F12 | G8: =G9+G10+G11+G12 | H8: =H9+H10+H11+H12 | I8: =I9+I10+I11+I12 | ... M8: =M9+M10+M11+M12 | N8: =SUM(B8:M8)
A9: 국산 홈서비스 가입 | B9: 2.5911616e+08 | C9: 2.2510905e+08 | D9: 3.0019555e+08 | E9: 3.3766357e+08 | F9: 2.9161854e+08 | G9: 3.5951239e+08 | H9: 3.8623657e+08 | I9: 3.9002851e+08 | J9: 3.6113751e+08 | K9: 3.4308063e+08 | L9: 3.4127495e+08 | M9: 3.3766357e+08 | N9: =SUM(B9:M9)
A10: 딜러 가입 | B10: 7773484.9 | C10: 6753271.4 | D10: 9005866.6 | E10: 10129907 | F10: 8748556.2 | G10: 10785372 | H10: 11587097 | I10: 11700855 | J10: 10834125 | K10: 10292419 | L10: 10238248 | M10: 10129907 | N10: =SUM(B10:M10)
A11: 수입 홈서비스 가입 | B11: 0 | C11: 0 | D11: 0 | E11: 50121702 | F11: 86573850 | G11: 1.0672974e+08 | H11: 1.1466345e+08 | I11: 1.1578917e+08 | J11: 1.072122e+08 | K11: 1.0185159e+08 | L11: 1.0131553e+08 | M11: 1.002434e+08 | N11: =SUM(B11:M11)
A12: EW 2.0 | B12: 0 | C12: 0 | D12: 0 | E12: 0 | F12: 0 | G12: 0 | H12: 0 | I12: 0 | J12: 8000000 | K12: 16000000 | L12: 16000000 | M12: 16000000 | N12: =SUM(B12:M12)
A13: 딜러 광고 | B13: 6280050 | C13: 6280050 | D13: 6280050 | E13: 6280050 | F13: 6280050 | G13: 6280050 | H13: 6280050 | I13: 6280050 | J13: 6280050 | K13: 6280050 | L13: 6280050 | M13: 6280050 | N13: =SUM(B13:M13)
A14: EW 2.0 광고 | B14: 0 | C14: 0 | D14: 0 | E14: 0 | F14: 0 | G14: 0 | H14: 0 | I14: 0 | J14: 4000000 | K14: 8000000 | L14: 8000000 | M14: 8000000 | N14: =SUM(B14:M14)
A15: 정비 쿠폰 | B15: 0 | C15: 0 | D15: 0 | E15: 4607566 | F15: 7958523 | G15: 9811405.1 | H15: 10540731 | I15: 10644217 | J15: 9855756 | K15: 9362968.2 | L15: 9313689.5 | M15: 9215131.9 | N15: =SUM(B15:M15)
A16: 정비 바우처 | B16: 0 | C16: 0 | D16: 0 | E16: 0 | F16: 0 | G16: 0 | H16: 10540731 | I16: 21288433 | J16: 19711512 | K16: 18725936 | L16: 18627379 | M16: 18430264 | N16: =SUM(B16:M16)
A17: [실적]
A18: 사업 매출 (거래액) | B18: 2.9314815e+08 | C18: 299294300 | D18: 4.4586206e+08 | E18: 4.0117718e+08 | F18: 4.5901939e+08 | N18: =SUM(B18:M18)
A19: 매출 달성률 (총) | B19: =IF(B18=0,"",IFERROR(B18/B7,"")) | C19: =IF(C18=0,"",IFERROR(C18/C7,"")) | D19: =IF(D18=0,"",IFERROR(D18/D7,"")) | E19: =IF(E18=0,"",IFERROR(E18/E7,"")) | F19: =IF(F18=0,"",IFERROR(F18/F7,"")) | G19: =IF(G18=0,"",IFERROR(G18/G7,"")) | H19: =IF(H18=0,"",IFERROR(H18/H7,"")) | I19: =IF(I18=0,"",IFERROR(I18/I7,"")) | ... N19: =IF(N18=0,"",IFERROR(N18/N7,""))
A21: Ⅱ. (참고) 안분 매출 — 재무팀 기준
A22: 안분 매출 (계획) | B22: 259801385 | C22: 2.6966696e+08 | D22: 2.4587628e+08 | E22: 3.2435285e+08 | F22: 403097807 | G22: 4.0222965e+08 | H22: 4.8685352e+08 | I22: 5.192703e+08 | J22: 520765118 | K22: 4.9186796e+08 | L22: 4.772651e+08 | M22: 4.7462959e+08 | N22: =SUM(B22:M22)
A23: 안분 매출 (실적) | B23: 286333145 | C23: 301034300 | D23: 2.9638327e+08 | E23: 347207980 | F23: 3.8009559e+08 | G23: 3.7151441e+08 | H23: 238448790 | I23: 1.2053491e+08 | N23: =SUM(B23:M23)
A24: 안분 매출 달성률 | B24: =IF(B23=0,"",IFERROR(B23/B22,"")) | C24: =IF(C23=0,"",IFERROR(C23/C22,"")) | D24: =IF(D23=0,"",IFERROR(D23/D22,"")) | E24: =IF(E23=0,"",IFERROR(E23/E22,"")) | F24: =IF(F23=0,"",IFERROR(F23/F22,"")) | G24: =IF(G23=0,"",IFERROR(G23/G22,"")) | H24: =IF(H23=0,"",IFERROR(H23/H22,"")) | I24: =IF(I23=0,"",IFERROR(I23/I22,"")) | ... N24: =IF(N23=0,"",IFERROR(N23/N22,""))
A26: Ⅲ. 가입 건수
A27: 가입 건수 (계획) | B27: =B28+B29+B30 | C27: =C28+C29+C30 | D27: =D28+D29+D30 | E27: =E28+E29+E30 | F27: =F28+F29+F30 | G27: =G28+G29+G30 | H27: =H28+H29+H30 | I27: =I28+I29+I30 | ... M27: =M28+M29+M30 | N27: =SUM(B27:M27)
A28: 국산 홈서비스 | B28: 707.1505 | C28: 614.34213 | D28: 819.25972 | E28: 921.51319 | F28: 795.8523 | G28: 981.14051 | H28: 1054.0731 | I28: 1064.4217 | J28: 985.5756 | K28: 936.29682 | L28: 931.36895 | M28: 921.51319 | N28: =SUM(B28:M28)
A29: 딜러 | B29: 21.214515 | C29: 18.430264 | D29: 24.577792 | E29: 27.645396 | F29: 23.875569 | G29: 29.434215 | H29: 31.622193 | I29: 31.93265 | J29: 29.567268 | K29: 28.088905 | L29: 27.941068 | M29: 27.645396 | N29: =SUM(B29:M29)
A30: 수입 EW 가입 | B30: 0 | C30: 0 | D30: 0 | E30: 50.121702 | F30: 86.57385 | G30: 106.72974 | H30: 114.66345 | I30: 115.78917 | J30: 107.2122 | K30: 101.85159 | L30: 101.31553 | M30: 100.2434 | N30: =SUM(B30:M30)
A31: 광고 건수 | B31: 350 | C31: 350 | D31: 350 | E31: 350 | F31: 350 | G31: 350 | H31: 350 | I31: 350 | J31: 350 | K31: 350 | L31: 350 | M31: 350 | N31: =SUM(B31:M31)
A32: 정비 쿠폰 건수 | B32: 0 | C32: 0 | D32: 0 | E32: 230.3783 | F32: 397.92615 | G32: 490.57026 | H32: 527.03655 | I32: 532.21083 | J32: 492.7878 | K32: 468.14841 | L32: 465.68447 | M32: 460.7566 | N32: =SUM(B32:M32)
A33: 정비 바우처 건수 | B33: 0 | C33: 0 | D33: 0 | E33: 0 | F33: 0 | G33: 0 | H33: 10.540731 | I33: 21.288433 | J33: 19.711512 | K33: 18.725936 | L33: 18.627379 | M33: 18.430264 | N33: =SUM(B33:M33)
A34: Ⅳ. 비용 / 이익
A35: 사업 비용 총계 (계획) | B35: =B36+B37 | C35: =C36+C37 | D35: =D36+D37 | E35: =E36+E37 | F35: =F36+F37 | G35: =G36+G37 | H35: =H36+H37 | I35: =I36+I37 | ... M35: =M36+M37 | N35: =SUM(B35:M35)
A36: 클레임 비용 | B36: 70603802 | C36: 61337566 | D36: 81797088 | E36: 96864878 | F36: 87852034 | G36: 1.0830551e+08 | H36: 1.1635635e+08 | I36: 117498695 | J36: 108795088 | K36: 1.0335533e+08 | L36: 1.0281136e+08 | M36: 1.0172341e+08 | N36: =SUM(B36:M36)
A37: 딜러 인센티브 | B37: 1775681.4 | C37: 1542636.1 | D37: 2057191.9 | E37: 2313954.2 | F37: 1998415 | G37: 2463680.7 | H37: 3465000 | I37: 3465000 | J37: 3465000 | K37: 3465000 | L37: 3465000 | M37: 3465000 | N37: =SUM(B37:M37)
A38: 사업 이익 (계획) = 매출 − 비용 | B38: =B7-B35 | C38: =C7-C35 | D38: =D7-D35 | E38: =E7-E35 | F38: =F7-F35 | G38: =G7-G35 | H38: =H7-H35 | I38: =I7-I35 | ... M38: =M7-M35 | N38: =SUM(B38:M38)
A39: 이익률 = 이익 ÷ 매출 | B39: =IFERROR(B38/B7,"") | C39: =IFERROR(C38/C7,"") | D39: =IFERROR(D38/D7,"") | E39: =IFERROR(E38/E7,"") | F39: =IFERROR(F38/F7,"") | G39: =IFERROR(G38/G7,"") | H39: =IFERROR(H38/H7,"") | I39: =IFERROR(I38/I7,"") | ... N39: =IFERROR(N38/N7,"")
A40: 영업일 | B40: 21 | C40: 17 | D40: 21 | E40: 22 | F40: 18 | G40: 22 | H40: 23 | I40: 20 | J40: 20 | K40: 21 | L40: 21 | M40: 22 | N40: =SUM(B40:M40)

Sheet Raw_금융
A1: 채널 | B1: 유입경로 | C1: 캐피탈 | L1: h | AB1: h/s 일반 : 홈서비스 & EP_fast + 다른 금융사 | AD1: EP : 홈서비스& EP | AF1: 일반금융 : 엔카
A2: H/S (일반) : | B2: 홈서비스, 믿고 | C2: 현대EP_FAST, 모든 금융사(현대EP 제외) | G2: SUMIFS(Raw_26!I:I, Raw_26!A:A, "1월", Raw_26!AB:AB, "홈서비스", Raw_26!E:E, "<>현대EP")
A3: H/S (EP) : | B3: 홈서비스, 믿고 | C3: 현대EP_FAST, 모든 금융사(현대EP 제외)
A4: 일반금융 : | B4: 엔카 | C4: 전부
K6: 수식X > 수기입력 총수수료
D8: 이거 한줄이에요 지우면 싹다 사라짐 | J8: 딜러 | K8: 엔카 | N8: 개인 | R8: 수수료(VAT포함) | W8: 딜러 | AC8: 엔카 관리( vat 포함) | AF8: 엔카 관리( vat 제외)
A9: 월 | C9: 캐피탈 | D9: 집행일 | E9: 캐피탈 | F9: 이름 | G9: 연락처 | H9: 차량번호 | I9: 대출금액 | J9: 금리 | K9: 총수수료 | L9: 지급수수료 | M9: 순수수료 | N9: 개인직접 | O9: 개인합계 | P9: 담당자 | Q9: 비고 | R9: 딜러명 | S9: 엔카직접 | T9: 엔카간접 | U9: 엔카합계 | V9: 딜러 | W9: 소득세 | X9: 지방세 | Y9: 실지급액 | Z9: 개인코드 환입액 | AA9: 매출 | AB9: 유입경로 | AC9: 총매출(vat포함) | AD9: 총비용 | AE9: 순매출 | AF9: 총매출(vat제외) | AG9: 총비용 | AH9: 순매출 | AI9: 실행 | AJ9: 개인 | AK9: 중도상환여부
A10: 1월 | B10: 2주차 | C10: 상환 | D10: 2026-01-09 | E10: 현대EP상환 | F10: 김상철 | G10: 010-4333-3071 | H10: 365모9595 | I10: -13200000 | J10: 0.067 | K10: 1.76 | L10: 0.13 | M10: 1.63 | P10: 정하은 | Q10: 홈서비스 60개월 / *당월철회 20260123 | Z10: 0 | AB10: 홈서비스 | AC10: -232320 | AD10: -17160 | AE10: -215160 | AF10: -211200 | AG10: -17160 | AH10: -194040 | AI10: 0 | AK10: 대출철회
A11: 1월 | B11: 5주차 | C11: 상환 | D11: 2026-01-29 | E11: 현대EP_fast상환 | F11: 김소라 | G11: 010-3382-0214 | H11: 58보7759 | I11: -5500000 | J11: 0.082 | K11: 1.76 | L11: 0.13 | M11: 1.63 | P11: 황채이 | Q11: 홈서비스 48개월 / 금리인하 0.5%적용건(8.7->8.2) /*중도상환 20260129 | Z11: 0 | AB11: 홈서비스 | AC11: -96800 | AD11: -7150 | AE11: -89650 | AF11: -88000 | AG11: -7150 | AH11: -80850 | AK11: 중도상환
A12: 1월 | B12: 5주차 | C12: 상환 | D12: 2026-01-26 | E12: 현대EP상환 | F12: 서영은 | G12: 010-8606-8913 | H12: 52더6798 | I12: -18900000 | J12: 0.107 | K12: 1.76 | L12: 0.13 | M12: 1.63 | P12: 정세빈 | Q12: 홈서비스 36개월 /*당월철회 20260108 | Z12: 0 | AB12: 홈서비스 | AC12: -332640 | AD12: -24570 | AE12: -308070 | AF12: -302400 | AG12: -24570 | AH12: -277830 | AK12: 대출철회
A13: 1월 | B13: 1주차 | C13: EP | D13: 46023 | E13: 현대EP | F13: 이국형 | G13: 010-4518-5764 | H13: 13주1485 | I13: 12000000 | J13: 0.068 | K13: 1.76 | L13: 0.13 | M13: 1.63 | P13: 황채이 | Q13: 홈서비스 48개월 | Z13: 0 | AB13: 홈서비스 | AC13: 211200 | AD13: 15600 | AE13: 195600 | AF13: 192000 | AG13: 15600 | AH13: 176400
A14: 1월 | B14: 1주차 | C14: EP | D14: 46023 | E14: 현대EP | F14: 이상준 | G14: 010-5125-2139 | H14: 43우5682 | I14: 61900000 | J14: 0.069 | K14: 1.76 | L14: 0.13 | M14: 1.63 | P14: 황채이 | Q14: 홈서비스 60개월 | Z14: 0 | AB14: 홈서비스 | AC14: 1089440 | AD14: 80470 | AE14: 1008970 | AF14: 990400 | AG14: 80470 | AH14: 909930 | AI14: 0
A15: 1월 | B15: 3주차 | C15: 상환 | D15: 2026-01-15 | E15: 현대EP상환 | F15: 한기찬 | G15: 010-6474-5487 | H15: 184가6686 | I15: -8000000 | J15: 0.057 | K15: 1.76 | L15: 0.13 | M15: 1.63 | P15: 최형주 | Q15: 홈서비스 36개월/ *중도상환 20260115 | Z15: 0 | AB15: 홈서비스 | AC15: -140800 | AD15: -10400 | AE15: -130400 | AF15: -128000 | AG15: -10400 | AH15: -117600 | AI15: 0 | AK15: 중도상환
A16: 5월 | B16: 22주차 | C16: EP | D16: 46169 | E16: 현대EP_fast | F16: 김도균 | G16: 010-2014-6185 | H16: 28구6353 | I16: 6600000 | J16: 0.089 | K16: 1.76 | L16: 0.5 | M16: 1.26 | P16: 임대경 | Z16: 0 | AB16: 엔카 | AC16: 116160 | AD16: 33000 | AE16: 83160 | AF16: 105600 | AG16: 33000 | AH16: 72600
A17: 1월 | B17: 5주차 | C17: 상환 | D17: 2026-01-27 | E17: 현대EP_fast상환 | F17: 윤성태 | G17: 010-7379-8080 | H17: 127머9065 | I17: -6600000 | J17: 0.093 | K17: 1.76 | L17: 0.13 | M17: 1.63 | P17: 정광호 | Q17: 홈서비스 48개월/ *중도상환 20260127 | Z17: 0 | AB17: 홈서비스 | AC17: -116160 | AD17: -8580 | AE17: -107580 | AF17: -105600 | AG17: -8580 | AH17: -97020 | AI17: 0 | AK17: 중도상환
A18: 5월 | B18: 22주차 | C18: EP | D18: 46169 | E18: BNKEP | F18: 최진명 | G18: 010-9622-9904 | H18: 264무6586 | I18: 6300000 | J18: 0.061 | K18: 1.65 | L18: 0.14 | M18: 1.51 | P18: 김수연 | Q18: 홈서비스 36개월 | Z18: 0 | AB18: 홈서비스 | AC18: 103950 | AD18: 8820 | AE18: 95130 | AF18: 94500 | AG18: 8820 | AH18: 85680
A19: 1월 | B19: 4주차 | C19: 상환 | D19: 2026-01-23 | E19: 현대EP_fast상환 | F19: 남승호 | G19: 1033952893 | H19: 16주1318 | I19: -3000000 | J19: 0.099 | K19: 1.76 | L19: 0.13 | M19: 1.63 | P19: 김나윤 | Q19: 홈서비스60개월 /*당월철회 20260128 | Z19: 0 | AB19: 홈서비스 | AC19: -52800 | AD19: -3900 | AE19: -48900 | AF19: -48000 | AG19: -3900 | AH19: -44100 | AI19: 0 | AK19: 대출철회
A20: 1월 | B20: 4주차 | C20: 상환 | D20: 2026-01-23 | E20: 현대EP_fast상환 | F20: 최한결 | G20: 010-7106-2417 | H20: 102거9777 | I20: -4600000 | J20: 0.057 | K20: 1.76 | L20: 0.13 | M20: 1.63 | P20: 최혁 | Q20: 홈서비스48개월 /*당월철회 20260119 | Z20: 0 | AB20: 홈서비스 | AC20: -80960 | AD20: -5980 | AE20: -74980 | AF20: -73600 | AG20: -5980 | AH20: -67620 | AI20: 0 | AK20: 대출철회
A21: 5월 | B21: 22주차 | C21: IM | D21: 46169 | E21: IM캐피탈 | F21: 이은표 | G21: 010-8149-0662 | H21: 322마4043 | I21: 16000000 | J21: 0.049 | K21: 1.1 | L21: 0.14 | M21: 0.96 | P21: 박소현 | Q21: 선상담 / 홈서비스 36개월 | Z21: 0 | AB21: 홈서비스 | AC21: 176000 | AD21: 22400 | AE21: 153600 | AF21: 160000 | AG21: 22400 | AH21: 137600 | AI21: 0
A22: 1월 | B22: 5주차 | C22: 상환 | D22: 2026-01-29 | E22: 현대EP_fast상환 | F22: 도형준 | G22: 010-2108-2106 | H22: 311어9093 | I22: -7500000 | J22: 0.105 | K22: 1.76 | L22: 0.13 | M22: 1.63 | P22: 정광호 | Q22: 홈서비스 60개월 /*당월철회 20260120 | Z22: 0 | AB22: 홈서비스 | AC22: -132000 | AD22: -9750 | AE22: -122250 | AF22: -120000 | AG22: -9750 | AH22: -110250 | AI22: 0 | AK22: 대출철회
A23: 1월 | B23: 4주차 | C23: 상환 | D23: 2026-01-19 | E23: 현대EP_fast상환 | F23: 조한나 | G23: 010-9052-7041 | H23: 20러0256 | I23: -23000000 | J23: 0.097 | K23: 1.76 | L23: 0.13 | M23: 1.63 | P23: 정하은 | Q23: 홈서비스 36개월 /*당월철회 20260123 | Z23: 0 | AB23: 홈서비스 | AC23: -404800 | AD23: -29900 | AE23: -374900 | AF23: -368000 | AG23: -29900 | AH23: -338100 | AI23: 0 | AK23: 대출철회
A24: 1월 | B24: 5주차 | C24: 상환 | D24: 2026-01-28 | E24: 현대EP_fast상환 | F24: 강준기 | G24: 010-4622-9517 | H24: 289노8326 | I24: -30000000 | J24: 0.093 | K24: 1.76 | L24: 0.13 | M24: 1.63 | P24: 정세빈 | Q24: 홈서비스 60개월 /*당월철회 20260126 | Z24: 0 | AB24: 홈서비스 | AC24: -528000 | AD24: -39000 | AE24: -489000 | AF24: -480000 | AG24: -39000 | AH24: -441000 | AK24: 대출철회
A25: 1월 | B25: 1주차 | C25: EP | D25: 46023 | E25: 현대EP | F25: 손봉기 | G25: 010-2224-1696 | H25: 153무2992 | I25: 4000000 | J25: 0.078 | K25: 1.76 | L25: 0.13 | M25: 1.63 | P25: 정광호 | Q25: 홈서비스 48개월 | Z25: 0 | AB25: 홈서비스 | AC25: 70400 | AD25: 5200 | AE25: 65200 | AF25: 64000 | AG25: 5200 | AH25: 58800
A26: 1월 | B26: 1주차 | C26: EP | D26: 46023 | E26: 현대EP | F26: 강태국 | G26: 010-8478-0464 | H26: 18러7584 | I26: 8000000 | J26: 0.101 | K26: 1.76 | L26: 0.13 | M26: 1.63 | P26: 최형주 | Q26: 홈서비스 60개월 | Z26: 0 | AB26: 홈서비스 | AC26: 140800 | AD26: 10400 | AE26: 130400 | AF26: 128000 | AG26: 10400 | AH26: 117600
A27: 5월 | B27: 22주차 | C27: IM | D27: 46169 | E27: IM캐피탈 | F27: 임창희 | G27: 010-8747-0910 | H27: 306구7082 | I27: 42000000 | J27: 0.049 | K27: 1.1 | L27: 0.14 | M27: 0.96 | P27: 박소현 | Q27: 선상담 / 홈서비스 60개월 | Z27: 0 | AB27: 홈서비스 | AC27: 462000 | AD27: 58800 | AE27: 403200 | AF27: 420000 | AG27: 58800 | AH27: 361200
A28: 1월 | B28: 1주차 | C28: EP | D28: 46024 | E28: 현대EP_fast | F28: 이정호 | G28: 010-4571-7976 | H28: 255러3776 | I28: 13300000 | J28: 0.097 | K28: 1.76 | L28: 0.13 | M28: 1.63 | P28: 정세빈 | Q28: 홈서비스 60개월 / 고객주도체결 | Z28: 0 | AB28: 홈서비스 | AC28: 234080 | AD28: 17290 | AE28: 216790 | AF28: 212800 | AG28: 17290 | AH28: 195510
A29: 1월 | B29: 1주차 | C29: EP | D29: 46024 | E29: 현대EP_fast | F29: 문용진 | G29: 010-8227-6361 | H29: 64마3681 | I29: 4200000 | J29: 0.115 | K29: 1.76 | L29: 0.13 | M29: 1.63 | P29: 정광호 | Q29: 홈서비스 24개월 | Z29: 0 | AB29: 홈서비스 | AC29: 73920 | AD29: 5460 | AE29: 68460 | AF29: 67200 | AG29: 5460 | AH29: 61740
A30: 1월 | B30: 4주차 | C30: 상환 | D30: 2026-01-22 | E30: 현대EP_fast상환 | F30: 한효빈 | G30: 010-7383-9054 | H30: 173다5045 | I30: -18600000 | J30: 0.087 | K30: 1.76 | L30: 0.13 | M30: 1.63 | P30: 박현민 | Q30: 홈서비스 24개월 /*당월철회 20260109 | Z30: 0 | AB30: 홈서비스 | AC30: -327360 | AD30: -24180 | AE30: -303180 | AF30: -297600 | AG30: -24180 | AH30: -273420 | AI30: 0 | AK30: 대출철회
A31: 1월 | B31: 1주차 | C31: EP | D31: 46024 | E31: 현대EP_fast | F31: 정민일 | G31: 010-9744-9736 | H31: 15모1967 | I31: 11900000 | J31: 0.085 | K31: 1.76 | L31: 0.4 | M31: 1.36 | P31: 박보람 | Z31: 0 | AB31: 엔카 | AC31: 209440 | AD31: 47600 | AE31: 161840 | AF31: 190400 | AG31: 47600 | AH31: 142800
A32: 5월 | B32: 22주차 | C32: IM | D32: 46169 | E32: IM캐피탈 | F32: 박슬기 | G32: 010-6328-0119 | H32: 396조5922 | I32: 47200000 | J32: 0.045 | K32: 1.1 | L32: 0.14 | M32: 0.96 | P32: 김수연 | Q32: 홈서비스 84개월 | Z32: 0 | AB32: 홈서비스 | AC32: 519200 | AD32: 66080 | AE32: 453120 | AF32: 472000 | AG32: 66080 | AH32: 405920 | AI32: 0
A33: 1월 | B33: 3주차 | C33: 상환 | D33: 2026-01-15 | E33: 현대EP_fast상환 | F33: 김국현 | G33: 010-3142-8779 | H33: 15루1661 | I33: -9900000 | J33: 0.067 | K33: 1.76 | L33: 0.13 | M33: 1.63 | P33: 최형주 | Q33: 홈서비스 36개월 / *12월실행 1월 중도상환 20260115 | Z33: 0 | AB33: 홈서비스 | AC33: -174240 | AD33: -12870 | AE33: -161370 | AF33: -158400 | AG33: -12870 | AH33: -145530 | AI33: 0 | AK33: 중도상환
A34: 1월 | B34: 1주차 | C34: EP | D34: 46024 | E34: 현대EP_fast | F34: 민경훈 | G34: 010-2052-2054 | H34: 183고3112 | I34: 19900000 | J34: 0.068 | K34: 1.76 | L34: 0.13 | M34: 1.63 | P34: 정세빈 | Q34: 홈서비스 60개월 / 카피아알선 | Z34: 0 | AB34: 홈서비스 | AC34: 350240 | AD34: 25870 | AE34: 324370 | AF34: 318400 | AG34: 25870 | AH34: 292530 | AI34: 0
A35: 5월 | B35: 21주차 | C35: IM | D35: 46164 | E35: IM캐피탈 | F35: 이광희 | G35: 010-8572-7875 | H35: 48거3082 | I35: 18000000 | J35: 0.045 | K35: 1.1 | L35: 0.4 | M35: 0.7 | P35: 장현경 | Z35: 0 | AB35: 엔카 | AC35: 198000 | AD35: 72000 | AE35: 126000 | AF35: 180000 | AG35: 72000 | AH35: 108000 | AI35: 0
A36: 5월 | B36: 22주차 | C36: EP | D36: 46169 | E36: 현대EP_fast | F36: 안하랑 | G36: 010-9506-0963 | H36: 268루5044 | I36: 26700000 | J36: 0.089 | K36: 1.76 | L36: 0.14 | M36: 1.62 | P36: 임대경 | Q36: 홈서비스 60개월 | Z36: 0 | AB36: 홈서비스 | AC36: 469920 | AD36: 37380 | AE36: 432540 | AF36: 427200 | AG36: 37380 | AH36: 389820 | AI36: 0
A37: 1월 | B37: 5주차 | C37: 상환 | D37: 2026-01-26 | E37: 현대EP_fast상환 | F37: 박영일 | G37: 010-4239-7002 | H37: 322오7853 | I37: -22500000 | J37: 0.124 | K37: 1.76 | L37: 0.13 | M37: 1.63 | P37: 장현경 | Q37: 선상담 / 홈서비스 36개월 /*당월철회 20260128 | Z37: 0 | AB37: 홈서비스 | AC37: -396000 | AD37: -29250 | AE37: -366750 | AF37: -360000 | AG37: -29250 | AH37: -330750 | AK37: 대출철회
A38: 1월 | B38: 5주차 | C38: 상환 | D38: 2026-01-30 | E38: 현대EP상환 | F38: 정윤호 | G38: 010-5258-3590 | H38: 43머0977 | I38: -6000000 | J38: 0.069 | K38: 1.76 | L38: 0.13 | M38: 1.63 | P38: 박현민 | Q38: 홈서비스 24개월/ *중도상환 20260130 | Z38: 0 | AB38: 홈서비스 | AC38: -105600 | AD38: -7800 | AE38: -97800 | AF38: -96000 | AG38: -7800 | AH38: -88200 | AI38: 0 | AK38: 중도상환
A39: 1월 | B39: 5주차 | C39: 상환 | D39: 2026-01-27 | E39: 현대EP_fast상환 | F39: 박겸주 | G39: 010-3567-6608 | H39: 52소3933 | I39: -16600000 | J39: 0.115 | K39: 1.76 | L39: 0.13 | M39: 1.63 | P39: 최혁 | Q39: 홈서비스36개월 /*당월철회 20260123 | Z39: 0 | AB39: 홈서비스 | AC39: -292160 | AD39: -21580 | AE39: -270580 | AF39: -265600 | AG39: -21580 | AH39: -244020 | AI39: 0 | AK39: 대출철회
A40: 1월 | B40: 1주차 | C40: IM | D40: 46024 | E40: IM캐피탈 | F40: 문남기 | G40: 010-8529-9181 | H40: 258조3410 | I40: 50000000 | J40: 0.049 | K40: 0.55 | L40: 0.13 | M40: 0.42 | P40: 박현민 | Q40: 홈서비스 36개월 / 사유 : 금리불만 | Z40: 0 | AB40: 홈서비스 | AC40: 275000 | AD40: 65000 | AE40: 210000 | AF40: 250000 | AG40: 65000 | AH40: 185000 | AI40: 0
A41: 1월 | B41: 1주차 | C41: IM | D41: 46024 | E41: IM캐피탈 | F41: 강인구 | G41: 010-4810-3562 | H41: 303부3477 | I41: 32700000 | J41: 0.039 | K41: 0.55 | L41: 0.13 | M41: 0.42 | P41: 황채이 | Q41: 홈서비스 60개월 / 사유 : 금리불만 | Z41: 0 | AB41: 홈서비스 | AC41: 179850 | AD41: 42510 | AE41: 137340 | AF41: 163500 | AG41: 42510 | AH41: 120990 | AI41: 0
A42: 1월 | B42: 1주차 | C42: EP | D42: 46023 | E42: 현대EP | F42: 이정윤 | G42: 010-4111-2291 | H42: 369부9945 | I42: 8900000 | J42: 0.079 | K42: 1.76 | L42: 0.13 | M42: 1.63 | P42: 최혁 | Q42: 홈서비스 48개월 | Z42: 0 | AB42: 홈서비스 | AC42: 156640 | AD42: 11570 | AE42: 145070 | AF42: 142400 | AG42: 11570 | AH42: 130830 | AI42: 0
...
